import sys

from test import support

import unittest


class Test_TestResult(unittest.TestCase):
    # Note: there are not separate tests for TestResult.wasSuccessful(),
    # TestResult.errors, TestResult.failures, TestResult.testsRun or
    # TestResult.shouldStop because these only have meaning in terms of
    # other TestResult methods.
    #
    # Accordingly, tests for the aforenamed attributes are incorporated
    # in with the tests for the defining methods.
    ################################################################

    def test_init(self):
        result = unittest.TestResult()

        self.assertTrue(result.wasSuccessful())
        self.assertEqual(len(result.errors), 0)
        self.assertEqual(len(result.failures), 0)
        self.assertEqual(result.testsRun, 0)
        self.assertEqual(result.shouldStop, False)
        self.assertIsNone(result._stdout_buffer)
        self.assertIsNone(result._stderr_buffer)

    # "This method can be called to signal that the set of tests being
    # run should be aborted by setting the TestResult's shouldStop
    # attribute to True."
    def test_stop(self):
        result = unittest.TestResult()

        result.stop()

        self.assertEqual(result.shouldStop, True)

    # "Called when the test case test is about to be run. The default
    # implementation simply increments the instance's testsRun counter."
    def test_startTest(self):
        class Foo(unittest.TestCase):
            def test_1(self):
                pass

        test = Foo('test_1')

        result = unittest.TestResult()

        result.startTest(test)

        self.assertTrue(result.wasSuccessful())
        self.assertEqual(len(result.errors), 0)
        self.assertEqual(len(result.failures), 0)
        self.assertEqual(result.testsRun, 1)
        self.assertEqual(result.shouldStop, False)

        result.stopTest(test)

    # "Called after the test case test has been executed, regardless of
    # the outcome. The default implementation does nothing."
    def test_stopTest(self):
        class Foo(unittest.TestCase):
            def test_1(self):
                pass

        test = Foo('test_1')

        result = unittest.TestResult()

        result.startTest(test)

        self.assertTrue(result.wasSuccessful())
        self.assertEqual(len(result.errors), 0)
        self.assertEqual(len(result.failures), 0)
        self.assertEqual(result.testsRun, 1)
        self.assertEqual(result.shouldStop, False)

        result.stopTest(test)

        # Same tests as above; make sure nothing has changed
        self.assertTrue(result.wasSuccessful())
        self.assertEqual(len(result.errors), 0)
        self.assertEqual(len(result.failures), 0)
        self.assertEqual(result.testsRun, 1)
        self.assertEqual(result.shouldStop, False)

    # "Called before and after tests are run. The default implementation does nothing."
    def test_startTestRun_stopTestRun(self):
        result = unittest.TestResult()
        result.startTestRun()
        result.stopTestRun()

    # "addSuccess(test)"
    # ...
    # "Called when the test case test succeeds"
    # ...
    # "wasSuccessful() - Returns True if all tests run so far have passed,
    # otherwise returns False"
    # ...
    # "testsRun - The total number of tests run so far."
    # ...
    # "errors - A list containing 2-tuples of TestCase instances and
    # formatted tracebacks. Each tuple represents a test which raised an
    # unexpected exception. Contains formatted
    # tracebacks instead of sys.exc_info() results."
    # ...
    # "failures - A list containing 2-tuples of TestCase instances and
    # formatted tracebacks. Each tuple represents a test where a failure was
    # explicitly signalled using the TestCase.fail*() or TestCase.assert*()
    # methods. Contains formatted tracebacks instead
    # of sys.exc_info() results."
    def test_addSuccess(self):
        class Foo(unittest.TestCase):
            def test_1(self):
                pass

        test = Foo('test_1')

        result = unittest.TestResult()

        result.startTest(test)
        result.addSuccess(test)
        result.stopTest(test)

        self.assertTrue(result.wasSuccessful())
        self.assertEqual(len(result.errors), 0)
        self.assertEqual(len(result.failures), 0)
        self.assertEqual(result.testsRun, 1)
        self.assertEqual(result.shouldStop, False)

    # "addFailure(test, err)"
    # ...
    # "Called when the test case test signals a failure. err is a tuple of
    # the form returned by sys.exc_info(): (type, value, traceback)"
    # ...
    # "wasSuccessful() - Returns True if all tests run so far have passed,
    # otherwise returns False"
    # ...
    # "testsRun - The total number of tests run so far."
    # ...
    # "errors - A list containing 2-tuples of TestCase instances and
    # formatted tracebacks. Each tuple represents a test which raised an
    # unexpected exception. Contains formatted
    # tracebacks instead of sys.exc_info() results."
    # ...
    # "failures - A list containing 2-tuples of TestCase instances and
    # formatted tracebacks. Each tuple represents a test where a failure was
    # explicitly signalled using the TestCase.fail*() or TestCase.assert*()
    # methods. Contains formatted tracebacks instead
    # of sys.exc_info() results."
    def test_addFailure(self):
        class Foo(unittest.TestCase):
            def test_1(self):
                pass

        test = Foo('test_1')
        try:
            test.fail("foo")
        except:
            exc_info_tuple = sys.exc_info()

        result = unittest.TestResult()

        result.startTest(test)
        result.addFailure(test, exc_info_tuple)
        result.stopTest(test)

        self.assertFalse(result.wasSuccessful())
        self.assertEqual(len(result.errors), 0)
        self.assertEqual(len(result.failures), 1)
        self.assertEqual(result.testsRun, 1)
        self.assertEqual(result.shouldStop, False)

        test_case, formatted_exc = result.failures[0]
        self.assertIs(test_case, test)
        self.assertIsInstance(formatted_exc, str)

    # "addError(test, err)"
    # ...
    # "Called when the test case test raises an unexpected exception err
    # is a tuple of the form returned by sys.exc_info():
    # (type, value, traceback)"
    # ...
    # "wasSuccessful() - Returns True if all tests run so far have passed,
    # otherwise returns False"
    # ...
    # "testsRun - The total number of tests run so far."
    # ...
    # "errors - A list containing 2-tuples of TestCase instances and
    # formatted tracebacks. Each tuple represents a test which raised an
    # unexpected exception. Contains formatted
    # tracebacks instead of sys.exc_info() results."
    # ...
    # "failures - A list containing 2-tuples of TestCase instances and
    # formatted tracebacks. Each tuple represents a test where a failure was
    # explicitly signalled using the TestCase.fail*() or TestCase.assert*()
    # methods. Contains formatted tracebacks instead
    # of sys.exc_info() results."
    def test_addError(self):
        class Foo(unittest.TestCase):
            def test_1(self):
                pass

        test = Foo('test_1')
        try:
            raise TypeError()
        except:
            exc_info_tuple = sys.exc_info()

        result = unittest.TestResult()

        result.startTest(test)
        result.addError(test, exc_info_tuple)
        result.stopTest(test)

        self.assertFalse(result.wasSuccessful())
        self.assertEqual(len(result.errors), 1)
        self.assertEqual(len(result.failures), 0)
        self.assertEqual(result.testsRun, 1)
        self.assertEqual(result.shouldStop, False)

        test_case, formatted_exc = result.errors[0]
        self.assertIs(test_case, test)
        self.assertIsInstance(formatted_exc, str)

    def test_addSubTest(self):
        class Foo(unittest.TestCase):
            def test_1(self):
                nonlocal subtest
                with self.subTest(foo=1):
                    subtest = self._subtest
                    try:
                        1/0
                    except ZeroDivisionError:
                        exc_info_tuple = sys.exc_info()
                    # Register an error by hand (to check the API)
                    result.addSubTest(test, subtest, exc_info_tuple)
                    # Now trigger a failure
                    self.fail("some recognizable failure")

        subtest = None
        test = Foo('test_1')
        result = unittest.TestResult()

        test.run(result)

        self.assertFalse(result.wasSuccessful())
        self.assertEqual(len(result.errors), 1)
        self.assertEqual(len(result.failures), 1)
        self.assertEqual(result.testsRun, 1)
        self.assertEqual(result.shouldStop, False)

        test_case, formatted_exc = result.errors[0]
        self.assertIs(test_case, subtest)
        self.assertIn("ZeroDivisionError", formatted_exc)
        test_case, formatted_exc = result.failures[0]
        self.assertIs(test_case, subtest)
        self.assertIn("some recognizable failure", formatted_exc)

    def testGetDescriptionWithoutDocstring(self):
        result = unittest.TextTestResult(None, True, 1)
        self.assertEqual(
                result.getDescription(self),
                'testGetDescriptionWithoutDocstring (' + __name__ +
                '.Test_TestResult)')

    def testGetSubTestDescriptionWithoutDocstring(self):
        with self.subTest(foo=1, bar=2):
            result = unittest.TextTestResult(None, True, 1)
            self.assertEqual(
                    result.getDescription(self._subtest),
                    'testGetSubTestDescriptionWithoutDocstring (' + __name__ +
                    '.Test_TestResult) (bar=2, foo=1)')
        with self.subTest('some message'):
            result = unittest.TextTestResult(None, True, 1)
            self.assertEqual(
                    result.getDescription(self._subtest),
                    'testGetSubTestDescriptionWithoutDocstring (' + __name__ +
                    '.Test_TestResult) [some message]')

    def testGetSubTestDescriptionWithoutDocstringAndParams(self):
        with self.subTest():
            result = unittest.TextTestResult(None, True, 1)
            self.assertEqual(
                    result.getDescription(self._subtest),
                    'testGetSubTestDescriptionWithoutDocstringAndParams '
                    '(' + __name__ + '.Test_TestResult) (<subtest>)')

    def testGetNestedSubTestDescriptionWithoutDocstring(self):
        with self.subTest(foo=1):
            with self.subTest(bar=2):
                result = unittest.TextTestResult(None, True, 1)
                self.assertEqual(
                        result.getDescription(self._subtest),
                        'testGetNestedSubTestDescriptionWithoutDocstring '
                        '(' + __name__ + '.Test_TestResult) (bar=2, foo=1)')


    def testStackFrameTrimming(self):
        class Frame(object):
            class tb_frame(object):
                f_globals = {}
        result = unittest.TestResult()
        self.assertFalse(result._is_relevant_tb_level(Frame))

        Frame.tb_frame.f_globals['__unittest'] = True
        self.assertTrue(result._is_relevant_tb_level(Frame))

    def testFailFast(self):
        result = unittest.TestResult()
        result._exc_info_to_string = lambda *_: ''
        result.failfast = True
        result.addError(None, None)
        self.assertTrue(result.shouldStop)

        result = unittest.TestResult()
        result._exc_info_to_string = lambda *_: ''
        result.failfast = True
        result.addFailure(None, None)
        self.assertTrue(result.shouldStop)

        result = unittest.TestResult()
        result._exc_info_to_string = lambda *_: ''
        result.failfast = True
        result.addUnexpectedSuccess(None)
        self.assertTrue(result.shouldStop)





